<!DOCTYPE html>
<html lang="en">

<head>
    <meta charset="UTF-8">
    <title>Promise</title>
</head>

<body>
</body>
<script type="text/javascript">
// ---------------------------------------------------------------------------
// Promise.reject()
// Promise.reject(reason)方法也会返回一个新的 Promise 实例,该实例的状态为rejected.
var p = Promise.reject('出错了');
// 等同于
var p = new Promise((resolve, reject) => reject('出错了'))

p.then(null, function(s) {
    console.log(s)
});
// 出错了

// 上面代码生成一个Promise对象的实例p,状态为rejected,【回调函数会立即执行】.
// 注意,【Promise.reject()方法的参数】,会原封不动地作为【reject的理由】,变成【后续方法(catch)的参数】. 
// 这一点与Promise.resolve方法不一致.(见下面例子)
// Promise.resolve方法如果接受thenable对象,会把thenable里then方法中resolve的参数传给后续方法

const thenable = {
    then(resolve, reject) {
        reject('出错了');
    }
};
Promise.reject(thenable)
    .catch(e => {
        console.log(e === thenable)
    })
// true

// 上面代码中,Promise.reject方法的参数是一个thenable对象,
// 执行以后,后面【catch方法的参数不是reject抛出的"出错了"这个字符串,而是thenable对象】.

// ---------------------------------------------------------------------------
// 两个有用的方法
// ES6的Promise API提供的方法不是很多,有些有用的方法可以自己部署.
// 下面介绍如何部署两个不在ES6之中、但很有用的方法.


// done() -------------------------------------------------
// Promise对象的回调链,不管以then方法或catch方法结尾,
// 要是最后一个方法抛出错误,都有可能无法捕捉到(因为Promise内部的错误不会冒泡到全局).
// 因此,我们可以提供一个done方法,总是处于回调链的尾端,保证抛出任何可能出现的错误.

asyncFunc()
    .then(f1)
    .catch(r1)
    .then(f2)
    .done();

// 它的实现代码相当简单. 如何理解function(onFulfilled, onRejected) ？ --- 只是方法参数.
Promise.prototype.done = function(onFulfilled, onRejected) {
    // Promise.then方法对应的回调函数：onFulfilled,onRejected,如何理解？ --- 只是方法参数.
    this.then(onFulfilled, onRejected)  
        .catch(function(reason) {
            // 抛出一个全局错误
            setTimeout(() => { throw reason }, 0);
        });
};
// 从上面代码可见,done方法的使用,可以【像then方法那样用】,提供Fulfilled和Rejected状态的回调函数,
// 也可以不提供任何参数.---- then方法没有参数,则表明回调不进行任何处理.
// 但不管怎样,done都会捕捉到任何可能出现的错误,并向全局抛出.


// finally() -------------------------------------------------
// finally方法用于指定不管Promise对象最后状态如何,都会执行的操作.
// 它与done方法的最大区别,它接受一个普通的回调函数作为参数,该函数不管怎样都必须执行.

// 下面是一个例子,服务器使用Promise处理请求,然后使用finally方法关掉服务器.
server.listen(0)
    .then(function() {
        // run test
    })
    .finally(server.stop);

// 它的实现也很简单.？？？？
Promise.prototype.finally = function(callback) {
    let P = this.constructor;
    return this.then(
        value => P.resolve(callback()).then(() => value),
        reason => P.resolve(callback()).then(() => { throw reason })
    );
};
// 上面代码中,不管前面的Promise是fulfilled还是rejected,都会执行回调函数callback.


// ---------------------------------------------------------------------------
// 应用：Promise.try()

// 实际开发中,经常遇到一种情况：不知道或者不想区分,函数f是同步函数还是异步操作,但是想用 Promise 来处理它.
// 因为这样就可以不管f是否包含异步操作,都用then方法指定下一步流程,用catch方法处理f抛出的错误.
// 一般就会采用下面的写法.
Promise.resolve().then(f)

// 上面的写法有一个缺点,就是如果f是同步函数,那么它会在【本轮事件循环的末尾执行】.

const f = () => console.log('now');
Promise.resolve().then(f);
console.log('next');
// next
// now

// 上面代码中,函数f是同步的,但是用 Promise 包装了以后,就变成异步执行了.


// 那么有没有一种方法,让同步函数同步执行,异步函数异步执行,并且让它们具有统一的 API 呢？
// 回答是可以的,并且还有两种写法.
// 第一种写法是用async函数来写.
const f = () => console.log('now');
(async() => f())();
console.log('next');
// now
// next

// 上面代码中,第二行是一个立即执行的匿名函数,会立即执行里面的async函数,
// 因此如果f是同步的,就会得到同步的结果;
// 如果f是异步的,就可以用then指定下一步,就像下面的写法.

(async() => f())()
.then(...)
// 需要注意的是,async () => f()会吃掉f()抛出的错误.
// 所以,如果想捕获错误,要使用promise.catch方法.
(async() => f())()
.then(...)
    .catch(...)
// ？？？？？？？以上写法也算统一的api？

// 第二种写法是使用new Promise().
const f = () => console.log('now');
(
    () => new Promise(
        resolve => resolve(f())
    )
)();
console.log('next');
// now
// next

// 上面代码也是使用立即执行的匿名函数,执行new Promise().这种情况下,同步函数也是同步执行的.


// 鉴于这是一个很常见的需求,所以现在有一个提案,提供Promise.try方法替代上面的写法.
const f = () => console.log('now');
Promise.try(f);
console.log('next');
// now
// next

// 事实上,Promise.try存在已久,Promise库Bluebird、Q和when,早就提供了这个方法.

// 由于Promise.try为所有操作提供了统一的处理机制,所以如果想用then方法管理流程,最好都用Promise.try包装一下.
// 这样有许多好处,其中一点就是可以更好地管理异常.

function getUsername(userId) {
    return database.users.get({ id: userId })
        .then(function(user) {
            return user.name;
        });
}
// 上面代码中,database.users.get()返回一个 Promise 对象,
// 如果抛出异步错误,可以用catch方法捕获,就像下面这样写.

database.users.get({ id: userId })
    .then(...)
    .catch(...)
// 但是database.users.get()可能还会抛出同步错误(比如数据库连接错误,具体要看实现方法),这时你就不得不用try...catch去捕获.

try {
    database.users.get({ id: userId })
        .then(...)
        .catch(...)
} catch (e) {
    // ...
}
// 上面这样的写法就很笨拙了,这时就可以统一用promise.catch()捕获所有同步和异步的错误.

Promise.try(database.users.get({ id: userId }))
    .then(...)
    .catch(...)

// 事实上,Promise.try就是模拟try代码块,就像promise.catch模拟的是catch代码块.
</script>

</html>